<?xml version='1.0'?>
<robot name='arm'>

<link name='world'/>

<joint name='base_joint' type='fixed'>
	<parent link='world'/>
	<child link='base_link'/>	
</joint>

<link name="base_link">
	<visual>
             <origin xyz="0 0 0.05" rpy="0 0 0"/>
             <geometry>
             	 	<box size="0.1 0.1 0.1"/>              
             </geometry>
             <material name="blue">
              		<color rgba="0 0 1 1"/>              
             </material>
	</visual> 
	<collision>
		<origin xyz="0 0 0.05" rpy="0 0 0"/>
         	<geometry>
              		<box size="0.1 0.1 0.1"/>              
        	</geometry>
	</collision>
	<inertial>
 		<mass value="3"/>
		<inertia ixx="0.0225" ixy="0" ixz="0" iyx="0" iyy="0.0225" iyz="0" izx="0" izy="0" izz="0.0225"/>
	</inertial>
</link>

<link name="link_one">
	<visual>
             <origin xyz="0 0 0.05" rpy="0 0 0"/>
             <geometry>
             	 	<box size="0.05 0.05 0.05"/>              
             </geometry>
             <material name="blue">
              		<color rgba="0 0 1 1"/>              
             </material>
	</visual> 
	<collision>
		<origin xyz="0 0 0.05" rpy="0 0 0"/>
         	<geometry>
              		<box size="0.05 0.05 0.05"/>              
        	</geometry>
	</collision>
	<inertial>
 		<mass value="1.5"/>
		<inertia ixx="0.01" ixy="0" ixz="0" iyx="0" iyy="0.01" iyz="0" izx="0" izy="0" izz="0.01"/>
	</inertial>
</link>

<joint name='joint_one' type='revolute'>
	<parent link="base_link"/>
	<child link="link_one"/>
	<origin xyz="0 0 0.075" rpy="0 0 0"/>
	<axis xyz="0 0 1"/>
	<limit effort="30" velocity="0.5" lower="-2.5" upper="2.5" />
</joint>

<link name="link_two">
	<visual>
		<origin xyz="0 0 0.09" rpy="0 0 0"/>
		<geometry>
			<box size="0.015 0.015 0.2"/>
		</geometry>
		<material name="darkgray">
			<color rgba="0.2 0.2 0.25 1"/>
		</material>
	</visual>
	<collision>	
		<origin xyz="0 0 0.09" rpy="0 0 1.57"/>
		<geometry>
			<box size="0.015 0.015 0.2"/>
		</geometry>
	</collision>
	<inertial>
		<mass value="0.5"/>
		<inertia ixx="0.01" ixy="0.0" ixz="0.0" iyy="0.005" iyz="0.0" izz="0.005"/>
	</inertial>
</link>

<joint name='joint_two' type='revolute'>
	<parent link="link_one"/>
	<child link="link_two"/>
	<origin xyz="0 0 0.09" rpy="0 0 0"/>
	<axis xyz="1 0 0"/>
	<limit effort="30" velocity="0.5" lower="-2.5" upper="2.5" />
</joint>

  <!-- ros_control plugin -->
<gazebo>
	<plugin name="gazebo_ros_control" filename="libgazebo_ros_control.so">
	<robotNamespace>arm</robotNamespace>
	<robotSimType>gazebo_ros_control/DefaultRobotHWSim</robotSimType>
	</plugin>
</gazebo>



  <!-- Base Link -->
  <gazebo reference="base_link">

  <material>Gazebo/Red</material>
  </gazebo>

  <!-- link_one-->
  <gazebo reference="link_one">

    <material>Gazebo/Green</material>
  </gazebo>
  
    <!--link_two-->
  <gazebo reference="link_two">

    <material>Gazebo/Blue</material>
  </gazebo>

<transmission name="tran1">
    <type>transmission_interface/SimpleTransmission</type>
    <joint name="joint_one">
      <hardwareInterface>hardware_interface/PositionJointInterface</hardwareInterface>
    </joint>
    <actuator name="motor1">
      <hardwareInterface>hardware_interface/PositionJointInterface</hardwareInterface>
      <mechanicalReduction>1</mechanicalReduction>
    </actuator>
</transmission>
  
<transmission name="tran1">
    <type>transmission_interface/SimpleTransmission</type>
    <joint name="joint_two">
      <hardwareInterface>hardware_interface/PositionJointInterface</hardwareInterface>
    </joint>
    <actuator name="motor1">
      <hardwareInterface>hardware_interface/PositionJointInterface</hardwareInterface>
      <mechanicalReduction>1</mechanicalReduction>
    </actuator>
</transmission>
  
</robot>





